<?xml version="1.0" ?>
<!-- =================================================================================== -->
<!-- |    This document was autogenerated by xacro from apptronik_minimal.xacro        | -->
<!-- |    EDITING THIS FILE BY HAND IS NOT RECOMMENDED                                 | -->
<!-- =================================================================================== -->
<!-- Written by Ryan Steindl <ryan.steindl@csiro.au> -->
<!-- August 2018 -->
<!-- data61, CSIRO (AU) -->
<!-- Note: order of includes matters! -->
<robot name="DSH1" xmlns:xacro="http://www.ros.org/wiki/xacro">
  <!-- Material colorization not working like desired, check out: -->
  <!-- http://gazebosim.org/tutorials/?tut=ros_urdf#Materials:Usingpropercolorsandtextures -->
  <!-- or -->
  <!-- https://bitbucket.org/osrf/gazebo/src/default/media/materials/scripts/gazebo.material?fileviewer=file-view-default -->
  <!-- 	<xacro:property name="pi" value="3.14159" /> -->
  <!-- Main body parameters -->
  <!-- body coxa link parameters -->
  <gazebo>
    <plugin filename="libgazebo_ros_control.so" name="gazebo_ros_control">
      <robotDescription>DSH1_description</robotDescription>
      <robotBaseLink>base_link</robotBaseLink>
      <statePublisherRate>1000.0</statePublisherRate>
    </plugin>
  </gazebo>
  <!-- Main body -->
  <!-- Base -->
  <link name="base_link">
    <inertial>
      <origin rpy="0 0 0" xyz="-0.00131 3e-05 0.07014"/>
      <mass value="0.005"/>
      <inertia ixx="0.0001" ixy="0.0001" ixz="0.0001" iyy="0.0001" iyz="0.0001" izz="0.0001"/>
    </inertial>
  </link>
  <link name="body_link">
    <visual>
      <origin rpy="0 0 0" xyz="0 0 0"/>
      <geometry>
        <mesh filename="package://meshes/ASM_DSH1_Body.dae"/>
      </geometry>
      <material name="grey">
        <color rgba="0.5 0.5 0.5 1"/>
      </material>
    </visual>
    <collision>
      <origin rpy="0 0 0" xyz="0 0 0.06"/>
      <geometry>
        <box size="0.7 0.24 0.12"/>
        <!--<mesh filename="${meshes_path}/ASM_Amazon_Body.dae" />-->
      </geometry>
    </collision>
    <inertial>
      <origin rpy="0 0 0" xyz="-0.00131 3e-05 0.07014"/>
      <mass value="7.6369"/>
      <inertia ixx="0.18873809131" ixy="-0.002190442" ixz="-0.00039570904" iyy="0.2495218632" iyz="-3.738463e-05" izz="0.1889091132"/>
    </inertial>
  </link>
  <joint name="body_joint" type="fixed">
    <parent link="base_link"/>
    <child link="body_link"/>
  </joint>
  <gazebo reference="body_link">
    <mu1>1.6</mu1>
    <mu2>1.6</mu2>
    <kp>1000000.0</kp>
    <kd>100.0</kd>
    <material>Gazebo/Grey</material>
    <selfCollide>True</selfCollide>
    <gravity>True</gravity>
  </gazebo>
  <!-- Body Coxa link -->
  <link name="AR_body_coxa_link">
    <visual>
      <origin rpy="0 0 0" xyz="0 0 0"/>
      <geometry>
        <!-- Normal corner configuration (AR & CL) -->
        <mesh filename="package://meshes/ASM_Body_Coxa_AR.dae"/>
      </geometry>
      <material name="blue">
        <color rgba="0 0 .8 1"/>
      </material>
    </visual>
    <collision>
      <origin rpy="0 0 0" xyz="0 -0.075 -0.015"/>
      <geometry>
        <box size="0.060 0.150 0.120"/>
        <!--<mesh filename="${meshes_path}/ASM_Body_Coxa_.dae" />-->
      </geometry>
    </collision>
    <inertial>
      <origin rpy="0 0 0" xyz="-0.05787 -0.09098 -0.02347"/>
      <mass value="1.49648"/>
      <inertia ixx="0.00237058393" ixy="-0.00037947708" ixz="0.00030252466" iyy="0.00404381682" iyz="-0.00014024756" izz="0.00433874382"/>
    </inertial>
  </link>
  <!-- Gazebo properties -->
  <gazebo reference="AR_body_coxa_link">
    <mu1>1.6</mu1>
    <mu2>1.6</mu2>
    <kp>1000000.0</kp>
    <kd>100.0</kd>
    <material>Gazebo/Blue</material>
    <selfCollide>True</selfCollide>
    <gravity>True</gravity>
  </gazebo>
  <!-- Body Coxa joint -->
  <joint name="ARbody_coxa_joint" type="fixed">
    <origin rpy="0 0 0.0" xyz="0.3 -0.0 0.0"/>
    <parent link="base_link"/>
    <child link="AR_body_coxa_link"/>
  </joint>
  <!-- Coxa link -->
  <link name="AR_coxa_link">
    <visual>
      <origin rpy="0 0 0" xyz="0 0 0"/>
      <geometry>
        <mesh filename="package://meshes/ASM_Coxa.dae"/>
      </geometry>
      <material name="white">
        <color rgba="1 1 1 1"/>
      </material>
    </visual>
    <collision>
      <origin rpy="0 0 0" xyz="0.032 0 0.062"/>
      <geometry>
        <box size="0.096 0.115 0.206"/>
        <!--<mesh filename="${meshes_path}/ASM_Coxa.dae" />-->
      </geometry>
    </collision>
    <inertial>
      <origin rpy="0 0 0" xyz="0.02698 -0.00028 0.0643"/>
      <mass value="2.40582"/>
      <inertia ixx="0.01288731354" ixy="-4.028532e-05" ixz="0.00060423369" iyy="0.0125301198" iyz="-4.000394e-05" izz="0.00456150593"/>
    </inertial>
  </link>
  <!-- Gazebo properties -->
  <gazebo reference="AR_coxa_link">
    <mu1>1.6</mu1>
    <mu2>1.6</mu2>
    <kp>1000000.0</kp>
    <kd>100.0</kd>
    <material>Gazebo/White</material>
    <selfCollide>True</selfCollide>
    <gravity>True</gravity>
  </gazebo>
  <!-- Coxa joint -->
  <joint name="AR_coxa_joint" type="revolute">
    <origin rpy="0.0 0.0 4.7123" xyz="0.0 -0.150 0.040"/>
    <parent link="AR_body_coxa_link"/>
    <child link="AR_coxa_link"/>
    <axis xyz="0 0 1"/>
    <!-- Normal corner configuration (AR & CL) -->
    <limit effort="75.0" lower="-0.6" upper="0.9" velocity="11.0"/>
    <dynamics damping="0.5" friction="0.0"/>
  </joint>
  <transmission name="AR_coxa_tran">
    <type>transmission_interface/SimpleTransmission</type>
    <joint name="AR_coxa_joint">
      <hardwareInterface>hardware_interface/EffortJointInterface</hardwareInterface>
    </joint>
    <actuator name="AR_coxa_motor">
      <hardwareInterface>hardware_interface/EffortJointInterface</hardwareInterface>
      <mechanicalReduction>1</mechanicalReduction>
    </actuator>
  </transmission>
  <!-- Femur link -->
  <link name="AR_femur_link">
    <visual>
      <origin rpy="0 0 0" xyz="0 0 0"/>
      <geometry>
        <mesh filename="package://meshes/ASM_Femur.dae"/>
      </geometry>
      <material name="orange">
        <color rgba="1 0.6 0 1"/>
      </material>
    </visual>
    <collision>
      <origin rpy="0 0 0" xyz="0.120 0.034 0.0"/>
      <geometry>
        <box size="0.240 0.112 0.115"/>
        <!-- <mesh filename="${meshes_path}/ASM_Femur.dae" /> -->
      </geometry>
    </collision>
    <inertial>
      <origin rpy="0 0 0" xyz="0.09968 0.02632 0.00017"/>
      <mass value="1.59736"/>
      <inertia ixx="0.00220546264" ixy="-0.00018851889" ixz="6.874375e-05" iyy="0.00860408815" iyz="-2.201149e-05" izz="0.00924003917"/>
    </inertial>
  </link>
  <!-- Gazebo properties -->
  <gazebo reference="AR_femur_link">
    <mu1>1.6</mu1>
    <mu2>1.6</mu2>
    <kp>1000000.0</kp>
    <kd>100.0</kd>
    <material>Gazebo/Orange</material>
    <selfCollide>True</selfCollide>
    <gravity>True</gravity>
  </gazebo>
  <!-- Femur joint -->
  <joint name="AR_femur_joint" type="revolute">
    <origin rpy="-1.5708 0 0" xyz="0.08 0 0.0"/>
    <parent link="AR_coxa_link"/>
    <child link="AR_femur_link"/>
    <axis xyz="0 0 1"/>
    <limit effort="75.0" lower="-1.1" upper="0.6" velocity="8.0"/>
    <dynamics damping="0.5" friction="0.0"/>
  </joint>
  <transmission name="AR_femur_tran">
    <type>transmission_interface/SimpleTransmission</type>
    <joint name="AR_femur_joint">
      <hardwareInterface>hardware_interface/EffortJointInterface</hardwareInterface>
    </joint>
    <actuator name="AR_femur_motor">
      <hardwareInterface>hardware_interface/EffortJointInterface</hardwareInterface>
      <mechanicalReduction>1</mechanicalReduction>
    </actuator>
  </transmission>
  <!-- Tibia link -->
  <link name="AR_tibia_link">
    <visual>
      <origin rpy="0 0 0" xyz="0 0 0"/>
      <geometry>
        <mesh filename="package://meshes/ASM_Tibia.dae"/>
      </geometry>
      <material name="grey">
        <color rgba="0.5 0.5 0.5 1"/>
      </material>
    </visual>
    <collision name="AR_tibia_link_collision">
      <origin rpy="0 1.5708 0" xyz="0.164 -0.015 0"/>
      <geometry>
        <cylinder length="0.244" radius="0.016"/>
        <!--<mesh filename="${meshes_path}/ASM_Tibia.dae" />-->
      </geometry>
    </collision>
    <inertial>
      <origin rpy="0 0 0" xyz="0.0675 -0.00776 0.00154"/>
      <mass value="0.4159"/>
      <inertia ixx="0.00040546855" ixy="-0.00020546604" ixz="-4.283075e-05" iyy="0.00584163406" iyz="4.84805e-06" izz="0.00560713232"/>
    </inertial>
  </link>
  <!-- Gazebo properties -->
  <gazebo reference="AR_tibia_link">
    <mu1>1.6</mu1>
    <mu2>1.6</mu2>
    <kp>1000000.0</kp>
    <kd>100.0</kd>
    <material>Gazebo/Grey</material>
    <!-- 			<selfCollide>True</selfCollide> -->
    <!-- 			<gravity>True</gravity> -->
  </gazebo>
  <!-- Tibia joint -->
  <joint name="AR_tibia_joint" type="revolute">
    <origin rpy="0 0 0" xyz="0.275 0 0"/>
    <parent link="AR_femur_link"/>
    <child link="AR_tibia_link"/>
    <axis xyz="0 0 1"/>
    <limit effort="75.0" lower="0.4" upper="2.4" velocity="11.0"/>
    <dynamics damping="0.5" friction="0.0"/>
  </joint>
  <transmission name="AR_tibia_tran">
    <type>transmission_interface/SimpleTransmission</type>
    <joint name="AR_tibia_joint">
      <hardwareInterface>hardware_interface/EffortJointInterface</hardwareInterface>
    </joint>
    <actuator name="AR_tibia_motor">
      <hardwareInterface>hardware_interface/EffortJointInterface</hardwareInterface>
      <mechanicalReduction>1</mechanicalReduction>
    </actuator>
  </transmission>
  <!-- Foot link, use sphere for enhancening collision properties, speeds up simulation! -->
  <link name="AR_foot_link">
    <visual>
      <geometry>
        <!--<mesh filename="${meshes_path}/AL_foot_link.dae" />-->
        <sphere radius="0.02"/>
        <!-- <sphere radius="0.03"/> -->
        <!-- <box size="0.05, 0.05, 0.05"/> -->
        <!-- <cylinder length="0.16" radius="0.035"/> -->
      </geometry>
      <origin rpy="0 0 0" xyz="0 0 0"/>
      <material name="grey">
        <color rgba="0.5 0.5 0.5 1"/>
      </material>
    </visual>
    <collision name="AR_foot_link_collision">
      <geometry>
        <sphere radius="0.02"/>
        <!-- <sphere radius="0.03"/> -->
        <!-- <box size="0.05, 0.05, 0.05"/> -->
        <!-- <cylinder length="0.16" radius="0.035"/> -->
      </geometry>
      <origin rpy="0 0 0" xyz="0 0 0"/>
    </collision>
    <inertial>
      <origin rpy="0 0 0" xyz="0 0 0"/>
      <mass value="0.0258"/>
      <inertia ixx="0" ixy="0" ixz="0" iyy="0" iyz="0" izz="0"/>
    </inertial>
  </link>
  <!-- Gazebo properties -->
  <gazebo reference="AR_foot_link">
    <mu1>1.6</mu1>
    <mu2>1.6</mu2>
    <kp>1000000.0</kp>
    <kd>100.0</kd>
    <material>Gazebo/Grey</material>
    <!-- 			<selfCollide>True</selfCollide> -->
    <!-- 			<gravity>True</gravity> -->
  </gazebo>
  <!-- Foot joint -->
  <joint name="AR_foot_joint" type="fixed">
    <!-- old without optoforce sensors xyz="1.521 0.12 0" -->
    <!-- new with optoforce sensors xyz="1.565 0.12 0" -->
    <origin rpy="0 0 0" xyz="0.343 -0.015 0"/>
    <parent link="AR_tibia_link"/>
    <child link="AR_foot_link"/>
    <axis xyz="0 0 0"/>
  </joint>
  <!-- Body Coxa link -->
  <link name="AL_body_coxa_link">
    <visual>
      <origin rpy="0 0 0" xyz="0 0 0"/>
      <geometry>
        <!-- Mirrored corner configuration (AL & CR) -->
        <mesh filename="package://meshes/ASM_Body_Coxa_CR.dae"/>
      </geometry>
      <material name="blue">
        <color rgba="0 0 .8 1"/>
      </material>
    </visual>
    <collision>
      <origin rpy="0 0 0" xyz="0 -0.075 -0.015"/>
      <geometry>
        <box size="0.060 0.150 0.120"/>
        <!--<mesh filename="${meshes_path}/ASM_Body_Coxa_.dae" />-->
      </geometry>
    </collision>
    <inertial>
      <origin rpy="0 0 0" xyz="0.05785 -0.09052 -0.0229"/>
      <mass value="1.49649"/>
      <inertia ixx="0.0023650205" ixy="0.0003700191" ixz="-0.00026263152" iyy="0.00404922506" iyz="-0.00013920303" izz="0.00435167001"/>
    </inertial>
  </link>
  <!-- Gazebo properties -->
  <gazebo reference="AL_body_coxa_link">
    <mu1>1.6</mu1>
    <mu2>1.6</mu2>
    <kp>1000000.0</kp>
    <kd>100.0</kd>
    <material>Gazebo/Blue</material>
    <selfCollide>True</selfCollide>
    <gravity>True</gravity>
  </gazebo>
  <!-- Body Coxa joint -->
  <joint name="ALbody_coxa_joint" type="fixed">
    <origin rpy="0 0 3.1416" xyz="0.3 0.0 0.0"/>
    <parent link="base_link"/>
    <child link="AL_body_coxa_link"/>
  </joint>
  <!-- Coxa link -->
  <link name="AL_coxa_link">
    <visual>
      <origin rpy="0 0 0" xyz="0 0 0"/>
      <geometry>
        <mesh filename="package://meshes/ASM_Coxa.dae"/>
      </geometry>
      <material name="white">
        <color rgba="1 1 1 1"/>
      </material>
    </visual>
    <collision>
      <origin rpy="0 0 0" xyz="0.032 0 0.062"/>
      <geometry>
        <box size="0.096 0.115 0.206"/>
        <!--<mesh filename="${meshes_path}/ASM_Coxa.dae" />-->
      </geometry>
    </collision>
    <inertial>
      <origin rpy="0 0 0" xyz="0.02698 -0.00028 0.0643"/>
      <mass value="2.40582"/>
      <inertia ixx="0.01288731354" ixy="-4.028532e-05" ixz="0.00060423369" iyy="0.0125301198" iyz="-4.000394e-05" izz="0.00456150593"/>
    </inertial>
  </link>
  <!-- Gazebo properties -->
  <gazebo reference="AL_coxa_link">
    <mu1>1.6</mu1>
    <mu2>1.6</mu2>
    <kp>1000000.0</kp>
    <kd>100.0</kd>
    <material>Gazebo/White</material>
    <selfCollide>True</selfCollide>
    <gravity>True</gravity>
  </gazebo>
  <!-- Coxa joint -->
  <joint name="AL_coxa_joint" type="revolute">
    <origin rpy="0.0 0.0 4.7123" xyz="0.0 -0.150 0.040"/>
    <parent link="AL_body_coxa_link"/>
    <child link="AL_coxa_link"/>
    <axis xyz="0 0 1"/>
    <!-- Mirrored corner configuration (AL & CR) -->
    <limit effort="75.0" lower="-0.9" upper="0.6" velocity="11.0"/>
    <dynamics damping="0.5" friction="0.0"/>
  </joint>
  <transmission name="AL_coxa_tran">
    <type>transmission_interface/SimpleTransmission</type>
    <joint name="AL_coxa_joint">
      <hardwareInterface>hardware_interface/EffortJointInterface</hardwareInterface>
    </joint>
    <actuator name="AL_coxa_motor">
      <hardwareInterface>hardware_interface/EffortJointInterface</hardwareInterface>
      <mechanicalReduction>1</mechanicalReduction>
    </actuator>
  </transmission>
  <!-- Femur link -->
  <link name="AL_femur_link">
    <visual>
      <origin rpy="0 0 0" xyz="0 0 0"/>
      <geometry>
        <mesh filename="package://meshes/ASM_Femur.dae"/>
      </geometry>
      <material name="orange">
        <color rgba="1 0.6 0 1"/>
      </material>
    </visual>
    <collision>
      <origin rpy="0 0 0" xyz="0.120 0.034 0.0"/>
      <geometry>
        <box size="0.240 0.112 0.115"/>
        <!-- <mesh filename="${meshes_path}/ASM_Femur.dae" /> -->
      </geometry>
    </collision>
    <inertial>
      <origin rpy="0 0 0" xyz="0.09968 0.02632 0.00017"/>
      <mass value="1.59736"/>
      <inertia ixx="0.00220546264" ixy="-0.00018851889" ixz="6.874375e-05" iyy="0.00860408815" iyz="-2.201149e-05" izz="0.00924003917"/>
    </inertial>
  </link>
  <!-- Gazebo properties -->
  <gazebo reference="AL_femur_link">
    <mu1>1.6</mu1>
    <mu2>1.6</mu2>
    <kp>1000000.0</kp>
    <kd>100.0</kd>
    <material>Gazebo/Orange</material>
    <selfCollide>True</selfCollide>
    <gravity>True</gravity>
  </gazebo>
  <!-- Femur joint -->
  <joint name="AL_femur_joint" type="revolute">
    <origin rpy="-1.5708 0 0" xyz="0.08 0 0.0"/>
    <parent link="AL_coxa_link"/>
    <child link="AL_femur_link"/>
    <axis xyz="0 0 1"/>
    <limit effort="75.0" lower="-1.1" upper="0.6" velocity="8.0"/>
    <dynamics damping="0.5" friction="0.0"/>
  </joint>
  <transmission name="AL_femur_tran">
    <type>transmission_interface/SimpleTransmission</type>
    <joint name="AL_femur_joint">
      <hardwareInterface>hardware_interface/EffortJointInterface</hardwareInterface>
    </joint>
    <actuator name="AL_femur_motor">
      <hardwareInterface>hardware_interface/EffortJointInterface</hardwareInterface>
      <mechanicalReduction>1</mechanicalReduction>
    </actuator>
  </transmission>
  <!-- Tibia link -->
  <link name="AL_tibia_link">
    <visual>
      <origin rpy="0 0 0" xyz="0 0 0"/>
      <geometry>
        <mesh filename="package://meshes/ASM_Tibia.dae"/>
      </geometry>
      <material name="grey">
        <color rgba="0.5 0.5 0.5 1"/>
      </material>
    </visual>
    <collision name="AL_tibia_link_collision">
      <origin rpy="0 1.5708 0" xyz="0.164 -0.015 0"/>
      <geometry>
        <cylinder length="0.244" radius="0.016"/>
        <!--<mesh filename="${meshes_path}/ASM_Tibia.dae" />-->
      </geometry>
    </collision>
    <inertial>
      <origin rpy="0 0 0" xyz="0.0675 -0.00776 0.00154"/>
      <mass value="0.4159"/>
      <inertia ixx="0.00040546855" ixy="-0.00020546604" ixz="-4.283075e-05" iyy="0.00584163406" iyz="4.84805e-06" izz="0.00560713232"/>
    </inertial>
  </link>
  <!-- Gazebo properties -->
  <gazebo reference="AL_tibia_link">
    <mu1>1.6</mu1>
    <mu2>1.6</mu2>
    <kp>1000000.0</kp>
    <kd>100.0</kd>
    <material>Gazebo/Grey</material>
    <!-- 			<selfCollide>True</selfCollide> -->
    <!-- 			<gravity>True</gravity> -->
  </gazebo>
  <!-- Tibia joint -->
  <joint name="AL_tibia_joint" type="revolute">
    <origin rpy="0 0 0" xyz="0.275 0 0"/>
    <parent link="AL_femur_link"/>
    <child link="AL_tibia_link"/>
    <axis xyz="0 0 1"/>
    <limit effort="75.0" lower="0.4" upper="2.4" velocity="11.0"/>
    <dynamics damping="0.5" friction="0.0"/>
  </joint>
  <transmission name="AL_tibia_tran">
    <type>transmission_interface/SimpleTransmission</type>
    <joint name="AL_tibia_joint">
      <hardwareInterface>hardware_interface/EffortJointInterface</hardwareInterface>
    </joint>
    <actuator name="AL_tibia_motor">
      <hardwareInterface>hardware_interface/EffortJointInterface</hardwareInterface>
      <mechanicalReduction>1</mechanicalReduction>
    </actuator>
  </transmission>
  <!-- Foot link, use sphere for enhancening collision properties, speeds up simulation! -->
  <link name="AL_foot_link">
    <visual>
      <geometry>
        <!--<mesh filename="${meshes_path}/AL_foot_link.dae" />-->
        <sphere radius="0.02"/>
        <!-- <sphere radius="0.03"/> -->
        <!-- <box size="0.05, 0.05, 0.05"/> -->
        <!-- <cylinder length="0.16" radius="0.035"/> -->
      </geometry>
      <origin rpy="0 0 0" xyz="0 0 0"/>
      <material name="grey">
        <color rgba="0.5 0.5 0.5 1"/>
      </material>
    </visual>
    <collision name="AL_foot_link_collision">
      <geometry>
        <sphere radius="0.02"/>
        <!-- <sphere radius="0.03"/> -->
        <!-- <box size="0.05, 0.05, 0.05"/> -->
        <!-- <cylinder length="0.16" radius="0.035"/> -->
      </geometry>
      <origin rpy="0 0 0" xyz="0 0 0"/>
    </collision>
    <inertial>
      <origin rpy="0 0 0" xyz="0 0 0"/>
      <mass value="0.0258"/>
      <inertia ixx="0" ixy="0" ixz="0" iyy="0" iyz="0" izz="0"/>
    </inertial>
  </link>
  <!-- Gazebo properties -->
  <gazebo reference="AL_foot_link">
    <mu1>1.6</mu1>
    <mu2>1.6</mu2>
    <kp>1000000.0</kp>
    <kd>100.0</kd>
    <material>Gazebo/Grey</material>
    <!-- 			<selfCollide>True</selfCollide> -->
    <!-- 			<gravity>True</gravity> -->
  </gazebo>
  <!-- Foot joint -->
  <joint name="AL_foot_joint" type="fixed">
    <!-- old without optoforce sensors xyz="1.521 0.12 0" -->
    <!-- new with optoforce sensors xyz="1.565 0.12 0" -->
    <origin rpy="0 0 0" xyz="0.343 -0.015 0"/>
    <parent link="AL_tibia_link"/>
    <child link="AL_foot_link"/>
    <axis xyz="0 0 0"/>
  </joint>
  <!-- Body Coxa link -->
  <link name="BR_body_coxa_link">
    <visual>
      <origin rpy="0 0 0" xyz="0 0 0"/>
      <geometry>
        <!-- Normal configuration (BR) -->
        <mesh filename="package://meshes/ASM_Body_Coxa_BR.dae"/>
      </geometry>
      <material name="blue">
        <color rgba="0 0 .8 1"/>
      </material>
    </visual>
    <collision>
      <origin rpy="0 0 0" xyz="0 -0.075 -0.015"/>
      <geometry>
        <box size="0.060 0.150 0.120"/>
        <!--<mesh filename="${meshes_path}/ASM_Body_Coxa_.dae" />-->
      </geometry>
    </collision>
    <inertial>
      <origin rpy="0 0 0" xyz="-0.05784 -0.09097 -0.02347"/>
      <mass value="1.49648"/>
      <inertia ixx="0.00236949742" ixy="-0.00038113993" ixz="0.00030648174" iyy="0.00404931192" iyz="-0.00013940059" izz="0.00434304717"/>
    </inertial>
  </link>
  <!-- Gazebo properties -->
  <gazebo reference="BR_body_coxa_link">
    <mu1>1.6</mu1>
    <mu2>1.6</mu2>
    <kp>1000000.0</kp>
    <kd>100.0</kd>
    <material>Gazebo/Blue</material>
    <selfCollide>True</selfCollide>
    <gravity>True</gravity>
  </gazebo>
  <!-- Body Coxa joint -->
  <joint name="BRbody_coxa_joint" type="fixed">
    <origin rpy="0 0 0.0" xyz="0.0 -0.0 0.0"/>
    <parent link="base_link"/>
    <child link="BR_body_coxa_link"/>
  </joint>
  <!-- Coxa link -->
  <link name="BR_coxa_link">
    <visual>
      <origin rpy="0 0 0" xyz="0 0 0"/>
      <geometry>
        <mesh filename="package://meshes/ASM_Coxa.dae"/>
      </geometry>
      <material name="white">
        <color rgba="1 1 1 1"/>
      </material>
    </visual>
    <collision>
      <origin rpy="0 0 0" xyz="0.032 0 0.062"/>
      <geometry>
        <box size="0.096 0.115 0.206"/>
        <!--<mesh filename="${meshes_path}/ASM_Coxa.dae" />-->
      </geometry>
    </collision>
    <inertial>
      <origin rpy="0 0 0" xyz="0.02698 -0.00028 0.0643"/>
      <mass value="2.40582"/>
      <inertia ixx="0.01288731354" ixy="-4.028532e-05" ixz="0.00060423369" iyy="0.0125301198" iyz="-4.000394e-05" izz="0.00456150593"/>
    </inertial>
  </link>
  <!-- Gazebo properties -->
  <gazebo reference="BR_coxa_link">
    <mu1>1.6</mu1>
    <mu2>1.6</mu2>
    <kp>1000000.0</kp>
    <kd>100.0</kd>
    <material>Gazebo/White</material>
    <selfCollide>True</selfCollide>
    <gravity>True</gravity>
  </gazebo>
  <!-- Coxa joint -->
  <joint name="BR_coxa_joint" type="revolute">
    <origin rpy="0.0 0.0 4.7123" xyz="0.0 -0.150 0.040"/>
    <parent link="BR_body_coxa_link"/>
    <child link="BR_coxa_link"/>
    <axis xyz="0 0 1"/>
    <!-- Normal configuration (BR) -->
    <limit effort="75.0" lower="-0.9" upper="0.9" velocity="11.0"/>
    <dynamics damping="0.5" friction="0.0"/>
  </joint>
  <transmission name="BR_coxa_tran">
    <type>transmission_interface/SimpleTransmission</type>
    <joint name="BR_coxa_joint">
      <hardwareInterface>hardware_interface/EffortJointInterface</hardwareInterface>
    </joint>
    <actuator name="BR_coxa_motor">
      <hardwareInterface>hardware_interface/EffortJointInterface</hardwareInterface>
      <mechanicalReduction>1</mechanicalReduction>
    </actuator>
  </transmission>
  <!-- Femur link -->
  <link name="BR_femur_link">
    <visual>
      <origin rpy="0 0 0" xyz="0 0 0"/>
      <geometry>
        <mesh filename="package://meshes/ASM_Femur.dae"/>
      </geometry>
      <material name="orange">
        <color rgba="1 0.6 0 1"/>
      </material>
    </visual>
    <collision>
      <origin rpy="0 0 0" xyz="0.120 0.034 0.0"/>
      <geometry>
        <box size="0.240 0.112 0.115"/>
        <!-- <mesh filename="${meshes_path}/ASM_Femur.dae" /> -->
      </geometry>
    </collision>
    <inertial>
      <origin rpy="0 0 0" xyz="0.09968 0.02632 0.00017"/>
      <mass value="1.59736"/>
      <inertia ixx="0.00220546264" ixy="-0.00018851889" ixz="6.874375e-05" iyy="0.00860408815" iyz="-2.201149e-05" izz="0.00924003917"/>
    </inertial>
  </link>
  <!-- Gazebo properties -->
  <gazebo reference="BR_femur_link">
    <mu1>1.6</mu1>
    <mu2>1.6</mu2>
    <kp>1000000.0</kp>
    <kd>100.0</kd>
    <material>Gazebo/Orange</material>
    <selfCollide>True</selfCollide>
    <gravity>True</gravity>
  </gazebo>
  <!-- Femur joint -->
  <joint name="BR_femur_joint" type="revolute">
    <origin rpy="-1.5708 0 0" xyz="0.08 0 0.0"/>
    <parent link="BR_coxa_link"/>
    <child link="BR_femur_link"/>
    <axis xyz="0 0 1"/>
    <limit effort="75.0" lower="-1.1" upper="0.6" velocity="8.0"/>
    <dynamics damping="0.5" friction="0.0"/>
  </joint>
  <transmission name="BR_femur_tran">
    <type>transmission_interface/SimpleTransmission</type>
    <joint name="BR_femur_joint">
      <hardwareInterface>hardware_interface/EffortJointInterface</hardwareInterface>
    </joint>
    <actuator name="BR_femur_motor">
      <hardwareInterface>hardware_interface/EffortJointInterface</hardwareInterface>
      <mechanicalReduction>1</mechanicalReduction>
    </actuator>
  </transmission>
  <!-- Tibia link -->
  <link name="BR_tibia_link">
    <visual>
      <origin rpy="0 0 0" xyz="0 0 0"/>
      <geometry>
        <mesh filename="package://meshes/ASM_Tibia.dae"/>
      </geometry>
      <material name="grey">
        <color rgba="0.5 0.5 0.5 1"/>
      </material>
    </visual>
    <collision name="BR_tibia_link_collision">
      <origin rpy="0 1.5708 0" xyz="0.164 -0.015 0"/>
      <geometry>
        <cylinder length="0.244" radius="0.016"/>
        <!--<mesh filename="${meshes_path}/ASM_Tibia.dae" />-->
      </geometry>
    </collision>
    <inertial>
      <origin rpy="0 0 0" xyz="0.0675 -0.00776 0.00154"/>
      <mass value="0.4159"/>
      <inertia ixx="0.00040546855" ixy="-0.00020546604" ixz="-4.283075e-05" iyy="0.00584163406" iyz="4.84805e-06" izz="0.00560713232"/>
    </inertial>
  </link>
  <!-- Gazebo properties -->
  <gazebo reference="BR_tibia_link">
    <mu1>1.6</mu1>
    <mu2>1.6</mu2>
    <kp>1000000.0</kp>
    <kd>100.0</kd>
    <material>Gazebo/Grey</material>
    <!-- 			<selfCollide>True</selfCollide> -->
    <!-- 			<gravity>True</gravity> -->
  </gazebo>
  <!-- Tibia joint -->
  <joint name="BR_tibia_joint" type="revolute">
    <origin rpy="0 0 0" xyz="0.275 0 0"/>
    <parent link="BR_femur_link"/>
    <child link="BR_tibia_link"/>
    <axis xyz="0 0 1"/>
    <limit effort="75.0" lower="0.4" upper="2.4" velocity="11.0"/>
    <dynamics damping="0.5" friction="0.0"/>
  </joint>
  <transmission name="BR_tibia_tran">
    <type>transmission_interface/SimpleTransmission</type>
    <joint name="BR_tibia_joint">
      <hardwareInterface>hardware_interface/EffortJointInterface</hardwareInterface>
    </joint>
    <actuator name="BR_tibia_motor">
      <hardwareInterface>hardware_interface/EffortJointInterface</hardwareInterface>
      <mechanicalReduction>1</mechanicalReduction>
    </actuator>
  </transmission>
  <!-- Foot link, use sphere for enhancening collision properties, speeds up simulation! -->
  <link name="BR_foot_link">
    <visual>
      <geometry>
        <!--<mesh filename="${meshes_path}/AL_foot_link.dae" />-->
        <sphere radius="0.02"/>
        <!-- <sphere radius="0.03"/> -->
        <!-- <box size="0.05, 0.05, 0.05"/> -->
        <!-- <cylinder length="0.16" radius="0.035"/> -->
      </geometry>
      <origin rpy="0 0 0" xyz="0 0 0"/>
      <material name="grey">
        <color rgba="0.5 0.5 0.5 1"/>
      </material>
    </visual>
    <collision name="BR_foot_link_collision">
      <geometry>
        <sphere radius="0.02"/>
        <!-- <sphere radius="0.03"/> -->
        <!-- <box size="0.05, 0.05, 0.05"/> -->
        <!-- <cylinder length="0.16" radius="0.035"/> -->
      </geometry>
      <origin rpy="0 0 0" xyz="0 0 0"/>
    </collision>
    <inertial>
      <origin rpy="0 0 0" xyz="0 0 0"/>
      <mass value="0.0258"/>
      <inertia ixx="0" ixy="0" ixz="0" iyy="0" iyz="0" izz="0"/>
    </inertial>
  </link>
  <!-- Gazebo properties -->
  <gazebo reference="BR_foot_link">
    <mu1>1.6</mu1>
    <mu2>1.6</mu2>
    <kp>1000000.0</kp>
    <kd>100.0</kd>
    <material>Gazebo/Grey</material>
    <!-- 			<selfCollide>True</selfCollide> -->
    <!-- 			<gravity>True</gravity> -->
  </gazebo>
  <!-- Foot joint -->
  <joint name="BR_foot_joint" type="fixed">
    <!-- old without optoforce sensors xyz="1.521 0.12 0" -->
    <!-- new with optoforce sensors xyz="1.565 0.12 0" -->
    <origin rpy="0 0 0" xyz="0.343 -0.015 0"/>
    <parent link="BR_tibia_link"/>
    <child link="BR_foot_link"/>
    <axis xyz="0 0 0"/>
  </joint>
  <!-- Body Coxa link -->
  <link name="BL_body_coxa_link">
    <visual>
      <origin rpy="0 0 0" xyz="0 0 0"/>
      <geometry>
        <!-- Normal configuration (BR) -->
        <mesh filename="package://meshes/ASM_Body_Coxa_BR.dae"/>
      </geometry>
      <material name="blue">
        <color rgba="0 0 .8 1"/>
      </material>
    </visual>
    <collision>
      <origin rpy="0 0 0" xyz="0 -0.075 -0.015"/>
      <geometry>
        <box size="0.060 0.150 0.120"/>
        <!--<mesh filename="${meshes_path}/ASM_Body_Coxa_.dae" />-->
      </geometry>
    </collision>
    <inertial>
      <origin rpy="0 0 0" xyz="-0.05784 -0.09097 -0.02347"/>
      <mass value="1.49648"/>
      <inertia ixx="0.00236949742" ixy="-0.00038113993" ixz="0.00030648174" iyy="0.00404931192" iyz="-0.00013940059" izz="0.00434304717"/>
    </inertial>
  </link>
  <!-- Gazebo properties -->
  <gazebo reference="BL_body_coxa_link">
    <mu1>1.6</mu1>
    <mu2>1.6</mu2>
    <kp>1000000.0</kp>
    <kd>100.0</kd>
    <material>Gazebo/Blue</material>
    <selfCollide>True</selfCollide>
    <gravity>True</gravity>
  </gazebo>
  <!-- Body Coxa joint -->
  <joint name="BLbody_coxa_joint" type="fixed">
    <origin rpy="0 0 3.1416" xyz="0.0 0.0 0.0"/>
    <parent link="base_link"/>
    <child link="BL_body_coxa_link"/>
  </joint>
  <!-- Coxa link -->
  <link name="BL_coxa_link">
    <visual>
      <origin rpy="0 0 0" xyz="0 0 0"/>
      <geometry>
        <mesh filename="package://meshes/ASM_Coxa.dae"/>
      </geometry>
      <material name="white">
        <color rgba="1 1 1 1"/>
      </material>
    </visual>
    <collision>
      <origin rpy="0 0 0" xyz="0.032 0 0.062"/>
      <geometry>
        <box size="0.096 0.115 0.206"/>
        <!--<mesh filename="${meshes_path}/ASM_Coxa.dae" />-->
      </geometry>
    </collision>
    <inertial>
      <origin rpy="0 0 0" xyz="0.02698 -0.00028 0.0643"/>
      <mass value="2.40582"/>
      <inertia ixx="0.01288731354" ixy="-4.028532e-05" ixz="0.00060423369" iyy="0.0125301198" iyz="-4.000394e-05" izz="0.00456150593"/>
    </inertial>
  </link>
  <!-- Gazebo properties -->
  <gazebo reference="BL_coxa_link">
    <mu1>1.6</mu1>
    <mu2>1.6</mu2>
    <kp>1000000.0</kp>
    <kd>100.0</kd>
    <material>Gazebo/White</material>
    <selfCollide>True</selfCollide>
    <gravity>True</gravity>
  </gazebo>
  <!-- Coxa joint -->
  <joint name="BL_coxa_joint" type="revolute">
    <origin rpy="0.0 0.0 4.7123" xyz="0.0 -0.150 0.040"/>
    <parent link="BL_body_coxa_link"/>
    <child link="BL_coxa_link"/>
    <axis xyz="0 0 1"/>
    <!-- Normal configuration (BR) -->
    <limit effort="75.0" lower="-0.9" upper="0.9" velocity="11.0"/>
    <dynamics damping="0.5" friction="0.0"/>
  </joint>
  <transmission name="BL_coxa_tran">
    <type>transmission_interface/SimpleTransmission</type>
    <joint name="BL_coxa_joint">
      <hardwareInterface>hardware_interface/EffortJointInterface</hardwareInterface>
    </joint>
    <actuator name="BL_coxa_motor">
      <hardwareInterface>hardware_interface/EffortJointInterface</hardwareInterface>
      <mechanicalReduction>1</mechanicalReduction>
    </actuator>
  </transmission>
  <!-- Femur link -->
  <link name="BL_femur_link">
    <visual>
      <origin rpy="0 0 0" xyz="0 0 0"/>
      <geometry>
        <mesh filename="package://meshes/ASM_Femur.dae"/>
      </geometry>
      <material name="orange">
        <color rgba="1 0.6 0 1"/>
      </material>
    </visual>
    <collision>
      <origin rpy="0 0 0" xyz="0.120 0.034 0.0"/>
      <geometry>
        <box size="0.240 0.112 0.115"/>
        <!-- <mesh filename="${meshes_path}/ASM_Femur.dae" /> -->
      </geometry>
    </collision>
    <inertial>
      <origin rpy="0 0 0" xyz="0.09968 0.02632 0.00017"/>
      <mass value="1.59736"/>
      <inertia ixx="0.00220546264" ixy="-0.00018851889" ixz="6.874375e-05" iyy="0.00860408815" iyz="-2.201149e-05" izz="0.00924003917"/>
    </inertial>
  </link>
  <!-- Gazebo properties -->
  <gazebo reference="BL_femur_link">
    <mu1>1.6</mu1>
    <mu2>1.6</mu2>
    <kp>1000000.0</kp>
    <kd>100.0</kd>
    <material>Gazebo/Orange</material>
    <selfCollide>True</selfCollide>
    <gravity>True</gravity>
  </gazebo>
  <!-- Femur joint -->
  <joint name="BL_femur_joint" type="revolute">
    <origin rpy="-1.5708 0 0" xyz="0.08 0 0.0"/>
    <parent link="BL_coxa_link"/>
    <child link="BL_femur_link"/>
    <axis xyz="0 0 1"/>
    <limit effort="75.0" lower="-1.1" upper="0.6" velocity="8.0"/>
    <dynamics damping="0.5" friction="0.0"/>
  </joint>
  <transmission name="BL_femur_tran">
    <type>transmission_interface/SimpleTransmission</type>
    <joint name="BL_femur_joint">
      <hardwareInterface>hardware_interface/EffortJointInterface</hardwareInterface>
    </joint>
    <actuator name="BL_femur_motor">
      <hardwareInterface>hardware_interface/EffortJointInterface</hardwareInterface>
      <mechanicalReduction>1</mechanicalReduction>
    </actuator>
  </transmission>
  <!-- Tibia link -->
  <link name="BL_tibia_link">
    <visual>
      <origin rpy="0 0 0" xyz="0 0 0"/>
      <geometry>
        <mesh filename="package://meshes/ASM_Tibia.dae"/>
      </geometry>
      <material name="grey">
        <color rgba="0.5 0.5 0.5 1"/>
      </material>
    </visual>
    <collision name="BL_tibia_link_collision">
      <origin rpy="0 1.5708 0" xyz="0.164 -0.015 0"/>
      <geometry>
        <cylinder length="0.244" radius="0.016"/>
        <!--<mesh filename="${meshes_path}/ASM_Tibia.dae" />-->
      </geometry>
    </collision>
    <inertial>
      <origin rpy="0 0 0" xyz="0.0675 -0.00776 0.00154"/>
      <mass value="0.4159"/>
      <inertia ixx="0.00040546855" ixy="-0.00020546604" ixz="-4.283075e-05" iyy="0.00584163406" iyz="4.84805e-06" izz="0.00560713232"/>
    </inertial>
  </link>
  <!-- Gazebo properties -->
  <gazebo reference="BL_tibia_link">
    <mu1>1.6</mu1>
    <mu2>1.6</mu2>
    <kp>1000000.0</kp>
    <kd>100.0</kd>
    <material>Gazebo/Grey</material>
    <!-- 			<selfCollide>True</selfCollide> -->
    <!-- 			<gravity>True</gravity> -->
  </gazebo>
  <!-- Tibia joint -->
  <joint name="BL_tibia_joint" type="revolute">
    <origin rpy="0 0 0" xyz="0.275 0 0"/>
    <parent link="BL_femur_link"/>
    <child link="BL_tibia_link"/>
    <axis xyz="0 0 1"/>
    <limit effort="75.0" lower="0.4" upper="2.4" velocity="11.0"/>
    <dynamics damping="0.5" friction="0.0"/>
  </joint>
  <transmission name="BL_tibia_tran">
    <type>transmission_interface/SimpleTransmission</type>
    <joint name="BL_tibia_joint">
      <hardwareInterface>hardware_interface/EffortJointInterface</hardwareInterface>
    </joint>
    <actuator name="BL_tibia_motor">
      <hardwareInterface>hardware_interface/EffortJointInterface</hardwareInterface>
      <mechanicalReduction>1</mechanicalReduction>
    </actuator>
  </transmission>
  <!-- Foot link, use sphere for enhancening collision properties, speeds up simulation! -->
  <link name="BL_foot_link">
    <visual>
      <geometry>
        <!--<mesh filename="${meshes_path}/AL_foot_link.dae" />-->
        <sphere radius="0.02"/>
        <!-- <sphere radius="0.03"/> -->
        <!-- <box size="0.05, 0.05, 0.05"/> -->
        <!-- <cylinder length="0.16" radius="0.035"/> -->
      </geometry>
      <origin rpy="0 0 0" xyz="0 0 0"/>
      <material name="grey">
        <color rgba="0.5 0.5 0.5 1"/>
      </material>
    </visual>
    <collision name="BL_foot_link_collision">
      <geometry>
        <sphere radius="0.02"/>
        <!-- <sphere radius="0.03"/> -->
        <!-- <box size="0.05, 0.05, 0.05"/> -->
        <!-- <cylinder length="0.16" radius="0.035"/> -->
      </geometry>
      <origin rpy="0 0 0" xyz="0 0 0"/>
    </collision>
    <inertial>
      <origin rpy="0 0 0" xyz="0 0 0"/>
      <mass value="0.0258"/>
      <inertia ixx="0" ixy="0" ixz="0" iyy="0" iyz="0" izz="0"/>
    </inertial>
  </link>
  <!-- Gazebo properties -->
  <gazebo reference="BL_foot_link">
    <mu1>1.6</mu1>
    <mu2>1.6</mu2>
    <kp>1000000.0</kp>
    <kd>100.0</kd>
    <material>Gazebo/Grey</material>
    <!-- 			<selfCollide>True</selfCollide> -->
    <!-- 			<gravity>True</gravity> -->
  </gazebo>
  <!-- Foot joint -->
  <joint name="BL_foot_joint" type="fixed">
    <!-- old without optoforce sensors xyz="1.521 0.12 0" -->
    <!-- new with optoforce sensors xyz="1.565 0.12 0" -->
    <origin rpy="0 0 0" xyz="0.343 -0.015 0"/>
    <parent link="BL_tibia_link"/>
    <child link="BL_foot_link"/>
    <axis xyz="0 0 0"/>
  </joint>
  &gt;
  
  <!-- Body Coxa link -->
  <link name="CR_body_coxa_link">
    <visual>
      <origin rpy="0 0 0" xyz="0 0 0"/>
      <geometry>
        <!-- Mirrored corner configuration (AL & CR) -->
        <mesh filename="package://meshes/ASM_Body_Coxa_CR.dae"/>
      </geometry>
      <material name="blue">
        <color rgba="0 0 .8 1"/>
      </material>
    </visual>
    <collision>
      <origin rpy="0 0 0" xyz="0 -0.075 -0.015"/>
      <geometry>
        <box size="0.060 0.150 0.120"/>
        <!--<mesh filename="${meshes_path}/ASM_Body_Coxa_.dae" />-->
      </geometry>
    </collision>
    <inertial>
      <origin rpy="0 0 0" xyz="0.05785 -0.09052 -0.0229"/>
      <mass value="1.49649"/>
      <inertia ixx="0.0023650205" ixy="0.0003700191" ixz="-0.00026263152" iyy="0.00404922506" iyz="-0.00013920303" izz="0.00435167001"/>
    </inertial>
  </link>
  <!-- Gazebo properties -->
  <gazebo reference="CR_body_coxa_link">
    <mu1>1.6</mu1>
    <mu2>1.6</mu2>
    <kp>1000000.0</kp>
    <kd>100.0</kd>
    <material>Gazebo/Blue</material>
    <selfCollide>True</selfCollide>
    <gravity>True</gravity>
  </gazebo>
  <!-- Body Coxa joint -->
  <joint name="CRbody_coxa_joint" type="fixed">
    <origin rpy="0 0 0.0" xyz="-0.3 -0.0 0.0"/>
    <parent link="base_link"/>
    <child link="CR_body_coxa_link"/>
  </joint>
  <!-- Coxa link -->
  <link name="CR_coxa_link">
    <visual>
      <origin rpy="0 0 0" xyz="0 0 0"/>
      <geometry>
        <mesh filename="package://meshes/ASM_Coxa.dae"/>
      </geometry>
      <material name="white">
        <color rgba="1 1 1 1"/>
      </material>
    </visual>
    <collision>
      <origin rpy="0 0 0" xyz="0.032 0 0.062"/>
      <geometry>
        <box size="0.096 0.115 0.206"/>
        <!--<mesh filename="${meshes_path}/ASM_Coxa.dae" />-->
      </geometry>
    </collision>
    <inertial>
      <origin rpy="0 0 0" xyz="0.02698 -0.00028 0.0643"/>
      <mass value="2.40582"/>
      <inertia ixx="0.01288731354" ixy="-4.028532e-05" ixz="0.00060423369" iyy="0.0125301198" iyz="-4.000394e-05" izz="0.00456150593"/>
    </inertial>
  </link>
  <!-- Gazebo properties -->
  <gazebo reference="CR_coxa_link">
    <mu1>1.6</mu1>
    <mu2>1.6</mu2>
    <kp>1000000.0</kp>
    <kd>100.0</kd>
    <material>Gazebo/White</material>
    <selfCollide>True</selfCollide>
    <gravity>True</gravity>
  </gazebo>
  <!-- Coxa joint -->
  <joint name="CR_coxa_joint" type="revolute">
    <origin rpy="0.0 0.0 4.7123" xyz="0.0 -0.150 0.040"/>
    <parent link="CR_body_coxa_link"/>
    <child link="CR_coxa_link"/>
    <axis xyz="0 0 1"/>
    <!-- Mirrored corner configuration (AL & CR) -->
    <limit effort="75.0" lower="-0.9" upper="0.6" velocity="11.0"/>
    <dynamics damping="0.5" friction="0.0"/>
  </joint>
  <transmission name="CR_coxa_tran">
    <type>transmission_interface/SimpleTransmission</type>
    <joint name="CR_coxa_joint">
      <hardwareInterface>hardware_interface/EffortJointInterface</hardwareInterface>
    </joint>
    <actuator name="CR_coxa_motor">
      <hardwareInterface>hardware_interface/EffortJointInterface</hardwareInterface>
      <mechanicalReduction>1</mechanicalReduction>
    </actuator>
  </transmission>
  <!-- Femur link -->
  <link name="CR_femur_link">
    <visual>
      <origin rpy="0 0 0" xyz="0 0 0"/>
      <geometry>
        <mesh filename="package://meshes/ASM_Femur.dae"/>
      </geometry>
      <material name="orange">
        <color rgba="1 0.6 0 1"/>
      </material>
    </visual>
    <collision>
      <origin rpy="0 0 0" xyz="0.120 0.034 0.0"/>
      <geometry>
        <box size="0.240 0.112 0.115"/>
        <!-- <mesh filename="${meshes_path}/ASM_Femur.dae" /> -->
      </geometry>
    </collision>
    <inertial>
      <origin rpy="0 0 0" xyz="0.09968 0.02632 0.00017"/>
      <mass value="1.59736"/>
      <inertia ixx="0.00220546264" ixy="-0.00018851889" ixz="6.874375e-05" iyy="0.00860408815" iyz="-2.201149e-05" izz="0.00924003917"/>
    </inertial>
  </link>
  <!-- Gazebo properties -->
  <gazebo reference="CR_femur_link">
    <mu1>1.6</mu1>
    <mu2>1.6</mu2>
    <kp>1000000.0</kp>
    <kd>100.0</kd>
    <material>Gazebo/Orange</material>
    <selfCollide>True</selfCollide>
    <gravity>True</gravity>
  </gazebo>
  <!-- Femur joint -->
  <joint name="CR_femur_joint" type="revolute">
    <origin rpy="-1.5708 0 0" xyz="0.08 0 0.0"/>
    <parent link="CR_coxa_link"/>
    <child link="CR_femur_link"/>
    <axis xyz="0 0 1"/>
    <limit effort="75.0" lower="-1.1" upper="0.6" velocity="8.0"/>
    <dynamics damping="0.5" friction="0.0"/>
  </joint>
  <transmission name="CR_femur_tran">
    <type>transmission_interface/SimpleTransmission</type>
    <joint name="CR_femur_joint">
      <hardwareInterface>hardware_interface/EffortJointInterface</hardwareInterface>
    </joint>
    <actuator name="CR_femur_motor">
      <hardwareInterface>hardware_interface/EffortJointInterface</hardwareInterface>
      <mechanicalReduction>1</mechanicalReduction>
    </actuator>
  </transmission>
  <!-- Tibia link -->
  <link name="CR_tibia_link">
    <visual>
      <origin rpy="0 0 0" xyz="0 0 0"/>
      <geometry>
        <mesh filename="package://meshes/ASM_Tibia.dae"/>
      </geometry>
      <material name="grey">
        <color rgba="0.5 0.5 0.5 1"/>
      </material>
    </visual>
    <collision name="CR_tibia_link_collision">
      <origin rpy="0 1.5708 0" xyz="0.164 -0.015 0"/>
      <geometry>
        <cylinder length="0.244" radius="0.016"/>
        <!--<mesh filename="${meshes_path}/ASM_Tibia.dae" />-->
      </geometry>
    </collision>
    <inertial>
      <origin rpy="0 0 0" xyz="0.0675 -0.00776 0.00154"/>
      <mass value="0.4159"/>
      <inertia ixx="0.00040546855" ixy="-0.00020546604" ixz="-4.283075e-05" iyy="0.00584163406" iyz="4.84805e-06" izz="0.00560713232"/>
    </inertial>
  </link>
  <!-- Gazebo properties -->
  <gazebo reference="CR_tibia_link">
    <mu1>1.6</mu1>
    <mu2>1.6</mu2>
    <kp>1000000.0</kp>
    <kd>100.0</kd>
    <material>Gazebo/Grey</material>
    <!-- 			<selfCollide>True</selfCollide> -->
    <!-- 			<gravity>True</gravity> -->
  </gazebo>
  <!-- Tibia joint -->
  <joint name="CR_tibia_joint" type="revolute">
    <origin rpy="0 0 0" xyz="0.275 0 0"/>
    <parent link="CR_femur_link"/>
    <child link="CR_tibia_link"/>
    <axis xyz="0 0 1"/>
    <limit effort="75.0" lower="0.4" upper="2.4" velocity="11.0"/>
    <dynamics damping="0.5" friction="0.0"/>
  </joint>
  <transmission name="CR_tibia_tran">
    <type>transmission_interface/SimpleTransmission</type>
    <joint name="CR_tibia_joint">
      <hardwareInterface>hardware_interface/EffortJointInterface</hardwareInterface>
    </joint>
    <actuator name="CR_tibia_motor">
      <hardwareInterface>hardware_interface/EffortJointInterface</hardwareInterface>
      <mechanicalReduction>1</mechanicalReduction>
    </actuator>
  </transmission>
  <!-- Foot link, use sphere for enhancening collision properties, speeds up simulation! -->
  <link name="CR_foot_link">
    <visual>
      <geometry>
        <!--<mesh filename="${meshes_path}/AL_foot_link.dae" />-->
        <sphere radius="0.02"/>
        <!-- <sphere radius="0.03"/> -->
        <!-- <box size="0.05, 0.05, 0.05"/> -->
        <!-- <cylinder length="0.16" radius="0.035"/> -->
      </geometry>
      <origin rpy="0 0 0" xyz="0 0 0"/>
      <material name="grey">
        <color rgba="0.5 0.5 0.5 1"/>
      </material>
    </visual>
    <collision name="CR_foot_link_collision">
      <geometry>
        <sphere radius="0.02"/>
        <!-- <sphere radius="0.03"/> -->
        <!-- <box size="0.05, 0.05, 0.05"/> -->
        <!-- <cylinder length="0.16" radius="0.035"/> -->
      </geometry>
      <origin rpy="0 0 0" xyz="0 0 0"/>
    </collision>
    <inertial>
      <origin rpy="0 0 0" xyz="0 0 0"/>
      <mass value="0.0258"/>
      <inertia ixx="0" ixy="0" ixz="0" iyy="0" iyz="0" izz="0"/>
    </inertial>
  </link>
  <!-- Gazebo properties -->
  <gazebo reference="CR_foot_link">
    <mu1>1.6</mu1>
    <mu2>1.6</mu2>
    <kp>1000000.0</kp>
    <kd>100.0</kd>
    <material>Gazebo/Grey</material>
    <!-- 			<selfCollide>True</selfCollide> -->
    <!-- 			<gravity>True</gravity> -->
  </gazebo>
  <!-- Foot joint -->
  <joint name="CR_foot_joint" type="fixed">
    <!-- old without optoforce sensors xyz="1.521 0.12 0" -->
    <!-- new with optoforce sensors xyz="1.565 0.12 0" -->
    <origin rpy="0 0 0" xyz="0.343 -0.015 0"/>
    <parent link="CR_tibia_link"/>
    <child link="CR_foot_link"/>
    <axis xyz="0 0 0"/>
  </joint>
  <!-- Body Coxa link -->
  <link name="CL_body_coxa_link">
    <visual>
      <origin rpy="0 0 0" xyz="0 0 0"/>
      <geometry>
        <!-- Normal corner configuration (AR & CL) -->
        <mesh filename="package://meshes/ASM_Body_Coxa_AR.dae"/>
      </geometry>
      <material name="blue">
        <color rgba="0 0 .8 1"/>
      </material>
    </visual>
    <collision>
      <origin rpy="0 0 0" xyz="0 -0.075 -0.015"/>
      <geometry>
        <box size="0.060 0.150 0.120"/>
        <!--<mesh filename="${meshes_path}/ASM_Body_Coxa_.dae" />-->
      </geometry>
    </collision>
    <inertial>
      <origin rpy="0 0 0" xyz="-0.05787 -0.09098 -0.02347"/>
      <mass value="1.49648"/>
      <inertia ixx="0.00237058393" ixy="-0.00037947708" ixz="0.00030252466" iyy="0.00404381682" iyz="-0.00014024756" izz="0.00433874382"/>
    </inertial>
  </link>
  <!-- Gazebo properties -->
  <gazebo reference="CL_body_coxa_link">
    <mu1>1.6</mu1>
    <mu2>1.6</mu2>
    <kp>1000000.0</kp>
    <kd>100.0</kd>
    <material>Gazebo/Blue</material>
    <selfCollide>True</selfCollide>
    <gravity>True</gravity>
  </gazebo>
  <!-- Body Coxa joint -->
  <joint name="CLbody_coxa_joint" type="fixed">
    <origin rpy="0 0 3.1416" xyz="-0.3 0.0 0.0"/>
    <parent link="base_link"/>
    <child link="CL_body_coxa_link"/>
  </joint>
  <!-- Coxa link -->
  <link name="CL_coxa_link">
    <visual>
      <origin rpy="0 0 0" xyz="0 0 0"/>
      <geometry>
        <mesh filename="package://meshes/ASM_Coxa.dae"/>
      </geometry>
      <material name="white">
        <color rgba="1 1 1 1"/>
      </material>
    </visual>
    <collision>
      <origin rpy="0 0 0" xyz="0.032 0 0.062"/>
      <geometry>
        <box size="0.096 0.115 0.206"/>
        <!--<mesh filename="${meshes_path}/ASM_Coxa.dae" />-->
      </geometry>
    </collision>
    <inertial>
      <origin rpy="0 0 0" xyz="0.02698 -0.00028 0.0643"/>
      <mass value="2.40582"/>
      <inertia ixx="0.01288731354" ixy="-4.028532e-05" ixz="0.00060423369" iyy="0.0125301198" iyz="-4.000394e-05" izz="0.00456150593"/>
    </inertial>
  </link>
  <!-- Gazebo properties -->
  <gazebo reference="CL_coxa_link">
    <mu1>1.6</mu1>
    <mu2>1.6</mu2>
    <kp>1000000.0</kp>
    <kd>100.0</kd>
    <material>Gazebo/White</material>
    <selfCollide>True</selfCollide>
    <gravity>True</gravity>
  </gazebo>
  <!-- Coxa joint -->
  <joint name="CL_coxa_joint" type="revolute">
    <origin rpy="0.0 0.0 4.7123" xyz="0.0 -0.150 0.040"/>
    <parent link="CL_body_coxa_link"/>
    <child link="CL_coxa_link"/>
    <axis xyz="0 0 1"/>
    <!-- Normal corner configuration (AR & CL) -->
    <limit effort="75.0" lower="-0.6" upper="0.9" velocity="11.0"/>
    <dynamics damping="0.5" friction="0.0"/>
  </joint>
  <transmission name="CL_coxa_tran">
    <type>transmission_interface/SimpleTransmission</type>
    <joint name="CL_coxa_joint">
      <hardwareInterface>hardware_interface/EffortJointInterface</hardwareInterface>
    </joint>
    <actuator name="CL_coxa_motor">
      <hardwareInterface>hardware_interface/EffortJointInterface</hardwareInterface>
      <mechanicalReduction>1</mechanicalReduction>
    </actuator>
  </transmission>
  <!-- Femur link -->
  <link name="CL_femur_link">
    <visual>
      <origin rpy="0 0 0" xyz="0 0 0"/>
      <geometry>
        <mesh filename="package://meshes/ASM_Femur.dae"/>
      </geometry>
      <material name="orange">
        <color rgba="1 0.6 0 1"/>
      </material>
    </visual>
    <collision>
      <origin rpy="0 0 0" xyz="0.120 0.034 0.0"/>
      <geometry>
        <box size="0.240 0.112 0.115"/>
        <!-- <mesh filename="${meshes_path}/ASM_Femur.dae" /> -->
      </geometry>
    </collision>
    <inertial>
      <origin rpy="0 0 0" xyz="0.09968 0.02632 0.00017"/>
      <mass value="1.59736"/>
      <inertia ixx="0.00220546264" ixy="-0.00018851889" ixz="6.874375e-05" iyy="0.00860408815" iyz="-2.201149e-05" izz="0.00924003917"/>
    </inertial>
  </link>
  <!-- Gazebo properties -->
  <gazebo reference="CL_femur_link">
    <mu1>1.6</mu1>
    <mu2>1.6</mu2>
    <kp>1000000.0</kp>
    <kd>100.0</kd>
    <material>Gazebo/Orange</material>
    <selfCollide>True</selfCollide>
    <gravity>True</gravity>
  </gazebo>
  <!-- Femur joint -->
  <joint name="CL_femur_joint" type="revolute">
    <origin rpy="-1.5708 0 0" xyz="0.08 0 0.0"/>
    <parent link="CL_coxa_link"/>
    <child link="CL_femur_link"/>
    <axis xyz="0 0 1"/>
    <limit effort="75.0" lower="-1.1" upper="0.6" velocity="8.0"/>
    <dynamics damping="0.5" friction="0.0"/>
  </joint>
  <transmission name="CL_femur_tran">
    <type>transmission_interface/SimpleTransmission</type>
    <joint name="CL_femur_joint">
      <hardwareInterface>hardware_interface/EffortJointInterface</hardwareInterface>
    </joint>
    <actuator name="CL_femur_motor">
      <hardwareInterface>hardware_interface/EffortJointInterface</hardwareInterface>
      <mechanicalReduction>1</mechanicalReduction>
    </actuator>
  </transmission>
  <!-- Tibia link -->
  <link name="CL_tibia_link">
    <visual>
      <origin rpy="0 0 0" xyz="0 0 0"/>
      <geometry>
        <mesh filename="package://meshes/ASM_Tibia.dae"/>
      </geometry>
      <material name="grey">
        <color rgba="0.5 0.5 0.5 1"/>
      </material>
    </visual>
    <collision name="CL_tibia_link_collision">
      <origin rpy="0 1.5708 0" xyz="0.164 -0.015 0"/>
      <geometry>
        <cylinder length="0.244" radius="0.016"/>
        <!--<mesh filename="${meshes_path}/ASM_Tibia.dae" />-->
      </geometry>
    </collision>
    <inertial>
      <origin rpy="0 0 0" xyz="0.0675 -0.00776 0.00154"/>
      <mass value="0.4159"/>
      <inertia ixx="0.00040546855" ixy="-0.00020546604" ixz="-4.283075e-05" iyy="0.00584163406" iyz="4.84805e-06" izz="0.00560713232"/>
    </inertial>
  </link>
  <!-- Gazebo properties -->
  <gazebo reference="CL_tibia_link">
    <mu1>1.6</mu1>
    <mu2>1.6</mu2>
    <kp>1000000.0</kp>
    <kd>100.0</kd>
    <material>Gazebo/Grey</material>
    <!-- 			<selfCollide>True</selfCollide> -->
    <!-- 			<gravity>True</gravity> -->
  </gazebo>
  <!-- Tibia joint -->
  <joint name="CL_tibia_joint" type="revolute">
    <origin rpy="0 0 0" xyz="0.275 0 0"/>
    <parent link="CL_femur_link"/>
    <child link="CL_tibia_link"/>
    <axis xyz="0 0 1"/>
    <limit effort="75.0" lower="0.4" upper="2.4" velocity="11.0"/>
    <dynamics damping="0.5" friction="0.0"/>
  </joint>
  <transmission name="CL_tibia_tran">
    <type>transmission_interface/SimpleTransmission</type>
    <joint name="CL_tibia_joint">
      <hardwareInterface>hardware_interface/EffortJointInterface</hardwareInterface>
    </joint>
    <actuator name="CL_tibia_motor">
      <hardwareInterface>hardware_interface/EffortJointInterface</hardwareInterface>
      <mechanicalReduction>1</mechanicalReduction>
    </actuator>
  </transmission>
  <!-- Foot link, use sphere for enhancening collision properties, speeds up simulation! -->
  <link name="CL_foot_link">
    <visual>
      <geometry>
        <!--<mesh filename="${meshes_path}/AL_foot_link.dae" />-->
        <sphere radius="0.02"/>
        <!-- <sphere radius="0.03"/> -->
        <!-- <box size="0.05, 0.05, 0.05"/> -->
        <!-- <cylinder length="0.16" radius="0.035"/> -->
      </geometry>
      <origin rpy="0 0 0" xyz="0 0 0"/>
      <material name="grey">
        <color rgba="0.5 0.5 0.5 1"/>
      </material>
    </visual>
    <collision name="CL_foot_link_collision">
      <geometry>
        <sphere radius="0.02"/>
        <!-- <sphere radius="0.03"/> -->
        <!-- <box size="0.05, 0.05, 0.05"/> -->
        <!-- <cylinder length="0.16" radius="0.035"/> -->
      </geometry>
      <origin rpy="0 0 0" xyz="0 0 0"/>
    </collision>
    <inertial>
      <origin rpy="0 0 0" xyz="0 0 0"/>
      <mass value="0.0258"/>
      <inertia ixx="0" ixy="0" ixz="0" iyy="0" iyz="0" izz="0"/>
    </inertial>
  </link>
  <!-- Gazebo properties -->
  <gazebo reference="CL_foot_link">
    <mu1>1.6</mu1>
    <mu2>1.6</mu2>
    <kp>1000000.0</kp>
    <kd>100.0</kd>
    <material>Gazebo/Grey</material>
    <!-- 			<selfCollide>True</selfCollide> -->
    <!-- 			<gravity>True</gravity> -->
  </gazebo>
  <!-- Foot joint -->
  <joint name="CL_foot_joint" type="fixed">
    <!-- old without optoforce sensors xyz="1.521 0.12 0" -->
    <!-- new with optoforce sensors xyz="1.565 0.12 0" -->
    <origin rpy="0 0 0" xyz="0.343 -0.015 0"/>
    <parent link="CL_tibia_link"/>
    <child link="CL_foot_link"/>
    <axis xyz="0 0 0"/>
  </joint>
  <!-- Import  Sensor payload (or imu only if no payload required)
  <xacro:unless value="$(arg gen_vertical_teststand)">
    <xacro:if value="$(arg gen_payload)">
      <xacro:include filename="$(find nav_backpack)/models/nav_backpack/model.urdf.xacro"/>
      <nav_backpack enable_lights="$(arg enable_lights)" namespace="$(arg nav_namespace)" parent="base_link">
        <origin xyz="0.22 0 0.141" rpy="0 0 0"/>
      </nav_backpack>
    </xacro:if>
    <xacro:unless value="$(arg gen_payload)">
      <xacro:include filename="$(find darpa_subt_hexapod)/robots/apptronik_xacro/imu_payload.xacro"/>
    </xacro:unless>
  </xacro:unless> -->
</robot>

